Workbook
Name _DLX1.INC: Goods!$A$2:$BR$14
Name _DLX2.INC: Services!$A$2:$BN$14
Name Bubble: "Bubble"
Name Chart: "Chart"
Name Heatmap: "Heatmap"
Name Histogram: "Histogram"
Name IQ_CH: 110000
Name IQ_CQ: 5000
Name IQ_CY: 10000
Name IQ_DAILY: 500000
Name IQ_FH: 100000
Name IQ_FQ: 500
Name IQ_FY: 1000
Name IQ_LTM: 2000
Name IQ_MONTH: 15000
Name IQ_NTM: 6000
Name IQ_WEEK: 50000
Name IQ_YTD: 3000
Name Map: "Map"
Name PieChart: "PieChart"
Name Scatter: "Scatter"
Name Series: "Series"
Name Table: "Table"

Sheet FAME Persistence2
A1: 8 | B1: To Harvard (target series)
A2: Global excl. EA | B2: $S$3 | C2: A1:A129 | D2: CFWDate | E2: 45917.317 | F2: TRUE | G2: CFWDate | H2: 1996 | I2: 2027 | J2: 0 | K2: Q | L2: FALSE | M2: TRUE | N2: FALSE | O2: -4142 | P2: start_period='1996',end_period='2027'
A3: Global excl. EA | B3: $T$3 | C3: A1:A129 | D3: diss'devo_all'EXT.AGGX.S25.Q.WL.MVOL_GR | E3: 45917.317 | F3: TRUE | G3: diss'devo_all'EXT.AGGX.S25.Q.WL.MVOL_GR | H3: 1996 | I3: 2027 | J3: 0 | K3: Q | L3: FALSE | M3: TRUE | N3: FALSE | O3: -4142 | P3: start_period='1996',end_period='2027'
A4: Global excl. EA | B4: $R$3 | E4: 0 | F4: FALSE | L4: FALSE | M4: FALSE | N4: FALSE | O4: 15
A5: Global excl. EA | B5: $Z$3 | E5: 0 | F5: FALSE | L5: FALSE | M5: FALSE | N5: FALSE | O5: -4142
A6: Global excl. EA | B6: $AA$3 | E6: 0 | F6: FALSE | L6: FALSE | M6: FALSE | N6: FALSE | O6: -4142
A7: Global excl. EA | B7: $AB$3 | E7: 0 | F7: FALSE | L7: FALSE | M7: FALSE | N7: FALSE | O7: -4142
A8: Global excl. EA | B8: $W$3 | E8: 0 | F8: FALSE | L8: FALSE | M8: FALSE | N8: FALSE | O8: -4142
A9: Global excl. EA | B9: $X$3 | E9: 0 | F9: FALSE | L9: FALSE | M9: FALSE | N9: FALSE | O9: -4142

Sheet To Harvard (target series)
B1: Volume, quarter-on-quarter growth
B2: Goods | C2: Services
A3: 35155
A4: 35246 | B4: 1.6081053 | C4: 1.8093444
A5: 35338 | B5: 2.4193289 | C5: 0.89975947
A6: 35430 | B6: 2.4686681 | C6: 3.0128388
A7: 35520 | B7: 2.9679549 | C7: 1.1282458
A8: 35611 | B8: 2.7480157 | C8: 1.2305381
A9: 35703 | B9: 2.1601952 | C9: 3.0144696
A10: 35795 | B10: 1.5449404 | C10: -0.17022097
A11: 35885 | B11: 0.44784121 | C11: 0.76748998
A12: 35976 | B12: -0.16315323 | C12: -0.85809251
A13: 36068 | B13: 2.0499639 | C13: -9.1442536
A14: 36160 | B14: -0.65285869 | C14: -0.19993014
A15: 36250 | B15: 1.6872479 | C15: 1.4767443
... A120: 45838 | B120: -1.0943906 | C120: 0.97917628

Sheet Global excl. EA
D1: q-o-q | F1: Contributions | V1: EXT.AGGX.S25. | X1: WL | Y1: Disc. | Z1: Goods | AA1: Services | AB1: Check | AC1: Goods | AD1: Services
C2: Date | D2: Goods | E2: Services | F2: Goods | G2: Services | H2: Total trade growth | L2: Raw | Q2: Rescaled (to match WL MVOL) | V2: 1996 | X2: =CONCATENATE("diss'devo_all'",'Global excl. EA'!$V$1,"Q.",X1,".MVOL_GR") -> diss'devo_all'EXT.AGGX.S25.Q.WL.MVOL_GR | Z2: Rescaled | AC2: Rescaled
L3: Goods | M3: Services | N3: Total trade growth | Q3: Goods | R3: Services | S3: Total trade growth | V3: 2027 | W3: =_xll.TIMESERIES_QUERY("CFWDate","start_period='"&'Global excl. EA'!$V$2&"',end_period='"&'Global excl. EA'!$V$3&"'","Q","Down","Heading","Normal") -> Refresh | X3: =_xll.TIMESERIES_QUERY(""&X2&"","start_period='"&'Global excl. EA'!$V$2&"',end_period='"&'Global excl. EA'!$V$3&"'","Q","Down","Heading","Normal") -> Refresh | Z3: Contributions | AC3: Quarter-on-quarter
A4: =IF(MONTH(C4)=3,YEAR(C4),"") -> 1996 | B4: =CONCATENATE("Q",IF(MONTH(C4)=3,"1",IF(MONTH(C4)=6,"2",IF(MONTH(C4)=9,"3",IF(MONTH(C4)=12,"4",NA()))))) -> Q1 | C4: =Goods!B15 -> 35155 | K4: 2012-19 | L4: =AVERAGE(F68:F99) -> 0.50681205 | M4: =AVERAGE(G68:G99) -> 0.192654 | N4: =AVERAGE(H68:H99) -> 0.69946606 | Q4: =AVERAGE(Z68:Z99) -> 0.40763874 | R4: =AVERAGE(AA68:AA99) -> 0.27575836 | S4: =AVERAGE(X68:X99) -> 0.6833971 | W4: 35155 | X4: 2.2239073 | Y4: =IF(ISNUMBER(H4),X4-H4,"") | Z4: =IF(ISNUMBER(F4),F4+F4/$H4*$Y4,"") | AA4: =IF(ISNUMBER(G4),G4+G4/$H4*$Y4,"") | AB4: =IF(ISNUMBER(Z4),SUM(Z4:AA4)-X4,"") | AC4: =IF(ISNUMBER(Z4),Z4/Goods!EH15,"") | AD4: =IF(ISNUMBER(AA4),AA4/Services!EH15,"")
A5: =IF(MONTH(C5)=3,YEAR(C5),"") | B5: =CONCATENATE("Q",IF(MONTH(C5)=3,"1",IF(MONTH(C5)=6,"2",IF(MONTH(C5)=9,"3",IF(MONTH(C5)=12,"4",NA()))))) -> Q2 | C5: =Goods!B16 -> 35246 | D5: =Goods!FL16 -> 1.6542974 | E5: =Services!FL16 -> 1.8613169 | F5: =Goods!EI16 -> 1.2761664 | G5: =Services!EI16 -> 0.42545048 | H5: =SUM(F5:G5) -> 1.7016169 | K5: 2021-23 | L5: =AVERAGE(F104:F115) -> 0.6051439 | M5: =AVERAGE(G104:G115) -> 0.64285535 | N5: =AVERAGE(H104:H115) -> 1.2479992 | Q5: =AVERAGE(Z104:Z115) -> 0.67615883 | R5: =AVERAGE(AA104:AA115) -> 0.51563937 | S5: =AVERAGE(X104:X115) -> 1.1917982 | W5: 35246 | X5: 1.6541035 | Y5: =IF(ISNUMBER(H5),X5-H5,"") -> -0.047513313 | Z5: =IF(ISNUMBER(F5),F5+F5/$H5*$Y5,"") -> 1.2405327 | AA5: =IF(ISNUMBER(G5),G5+G5/$H5*$Y5,"") -> 0.41357086 | AB5: =IF(ISNUMBER(Z5),SUM(Z5:AA5)-X5,"") -> -2.220446e-16 | AC5: =IF(ISNUMBER(Z5),Z5/Goods!EH16,"") -> 1.6081053 | AD5: =IF(ISNUMBER(AA5),AA5/Services!EH16,"") -> 1.8093444
A6: =IF(MONTH(C6)=3,YEAR(C6),"") | B6: =CONCATENATE("Q",IF(MONTH(C6)=3,"1",IF(MONTH(C6)=6,"2",IF(MONTH(C6)=9,"3",IF(MONTH(C6)=12,"4",NA()))))) -> Q3 | C6: =Goods!B17 -> 35338 | D6: =Goods!FL17 -> 2.3351528 | E6: =Services!FL17 -> 0.86845398 | F6: =Goods!EI17 -> 1.8039551 | G6: =Services!EI17 -> 0.19755485 | H6: =SUM(F6:G6) -> 2.0015099 | J6: 2024 | K6: Q1 | L6: =F116 -> 1.0933232 | M6: =G116 -> -0.053436631 | N6: =H116 -> 1.0398866 | Q6: =Z116 -> 0.6897696 | R6: =AA116 -> -0.033712779 | S6: =X116 -> 0.65605682 | W6: 35338 | X6: 2.0736591 | Y6: =IF(ISNUMBER(H6),X6-H6,"") -> 0.072149196 | Z6: =IF(ISNUMBER(F6),F6+F6/$H6*$Y6,"") -> 1.868983 | AA6: =IF(ISNUMBER(G6),G6+G6/$H6*$Y6,"") -> 0.20467618 | AB6: =IF(ISNUMBER(Z6),SUM(Z6:AA6)-X6,"") -> 0 | AC6: =IF(ISNUMBER(Z6),Z6/Goods!EH17,"") -> 2.4193289 | AD6: =IF(ISNUMBER(AA6),AA6/Services!EH17,"") -> 0.89975947
A7: =IF(MONTH(C7)=3,YEAR(C7),"") | B7: =CONCATENATE("Q",IF(MONTH(C7)=3,"1",IF(MONTH(C7)=6,"2",IF(MONTH(C7)=9,"3",IF(MONTH(C7)=12,"4",NA()))))) -> Q4 | C7: =Goods!B18 -> 35430 | D7: =Goods!FL18 -> 2.676626 | E7: =Services!FL18 -> 3.2666371 | F7: =Goods!EI18 -> 2.0719505 | G7: =Services!EI18 -> 0.73796469 | H7: =SUM(F7:G7) -> 2.8099152 | K7: Q2 | L7: =F117 -> 1.1657392 | M7: =G117 -> 0.30278687 | N7: =H117 -> 1.4685261 | Q7: =Z117 -> 1.5583962 | R7: =AA117 -> 0.40477483 | S7: =X117 -> 1.963171 | W7: 35430 | X7: 2.5916015 | Y7: =IF(ISNUMBER(H7),X7-H7,"") -> -0.21831372 | Z7: =IF(ISNUMBER(F7),F7+F7/$H7*$Y7,"") -> 1.9109723 | AA7: =IF(ISNUMBER(G7),G7+G7/$H7*$Y7,"") -> 0.68062921 | AB7: =IF(ISNUMBER(Z7),SUM(Z7:AA7)-X7,"") -> 0 | AC7: =IF(ISNUMBER(Z7),Z7/Goods!EH18,"") -> 2.4686681 | AD7: =IF(ISNUMBER(AA7),AA7/Services!EH18,"") -> 3.0128388
A8: =IF(MONTH(C8)=3,YEAR(C8),"") -> 1997 | B8: =CONCATENATE("Q",IF(MONTH(C8)=3,"1",IF(MONTH(C8)=6,"2",IF(MONTH(C8)=9,"3",IF(MONTH(C8)=12,"4",NA()))))) -> Q1 | C8: =Goods!B19 -> 35520 | D8: =Goods!FL19 -> 3.5398072 | E8: =Services!FL19 -> 1.3456311 | F8: =Goods!EI19 -> 2.7467637 | G8: =Services!EI19 -> 0.30146953 | H8: =SUM(F8:G8) -> 3.0482332 | K8: Q3 | L8: =F118 -> 1.1321191 | M8: =G118 -> 0.28768116 | N8: =H118 -> 1.4198002 | Q8: =Z118 -> 1.2792024 | R8: =AA118 -> 0.3250563 | S8: =X118 -> 1.6042587 | W8: 35520 | X8: 2.5557942 | Y8: =IF(ISNUMBER(H8),X8-H8,"") -> -0.492439 | Z8: =IF(ISNUMBER(F8),F8+F8/$H8*$Y8,"") -> 2.3030268 | AA8: =IF(ISNUMBER(G8),G8+G8/$H8*$Y8,"") -> 0.25276744 | AB8: =IF(ISNUMBER(Z8),SUM(Z8:AA8)-X8,"") -> 0 | AC8: =IF(ISNUMBER(Z8),Z8/Goods!EH19,"") -> 2.9679549 | AD8: =IF(ISNUMBER(AA8),AA8/Services!EH19,"") -> 1.1282458
A9: =IF(MONTH(C9)=3,YEAR(C9),"") | B9: =CONCATENATE("Q",IF(MONTH(C9)=3,"1",IF(MONTH(C9)=6,"2",IF(MONTH(C9)=9,"3",IF(MONTH(C9)=12,"4",NA()))))) -> Q2 | C9: =Goods!B20 -> 35611 | D9: =Goods!FL20 -> 3.3753527 | E9: =Services!FL20 -> 1.5114543 | F9: =Goods!EI20 -> 2.6293307 | G9: =Services!EI20 -> 0.3340623 | H9: =SUM(F9:G9) -> 2.963393 | K9: Q4 | L9: =F119 -> 0.34487496 | M9: =G119 -> 0.41252089 | N9: =H119 -> 0.75739586 | Q9: =Z119 -> 0.20388025 | R9: =AA119 -> 0.24387059 | S9: =X119 -> 0.44775084 | W9: 35611 | X9: 2.4126221 | Y9: =IF(ISNUMBER(H9),X9-H9,"") -> -0.55077095 | Z9: =IF(ISNUMBER(F9),F9+F9/$H9*$Y9,"") -> 2.140648 | AA9: =IF(ISNUMBER(G9),G9+G9/$H9*$Y9,"") -> 0.27197408 | AB9: =IF(ISNUMBER(Z9),SUM(Z9:AA9)-X9,"") -> 0 | AC9: =IF(ISNUMBER(Z9),Z9/Goods!EH20,"") -> 2.7480157 | AD9: =IF(ISNUMBER(AA9),AA9/Services!EH20,"") -> 1.2305381
A10: =IF(MONTH(C10)=3,YEAR(C10),"") | B10: =CONCATENATE("Q",IF(MONTH(C10)=3,"1",IF(MONTH(C10)=6,"2",IF(MONTH(C10)=9,"3",IF(MONTH(C10)=12,"4",NA()))))) -> Q3 | C10: =Goods!B21 -> 35703 | D10: =Goods!FL21 -> 2.2096154 | E10: =Services!FL21 -> 3.0834336 | F10: =Goods!EI21 -> 1.7276793 | G10: =Services!EI21 -> 0.67252336 | H10: =SUM(F10:G10) -> 2.4002026 | J10: 2025 | K10: Q1 | L10: =F120 -> 3.4240533 | M10: =G120 -> -0.049200207 | N10: =H120 -> 3.3748531 | Q10: =Z120 -> 1.688967 | R10: =AA120 -> -0.024268759 | S10: =X120 -> 1.6646982 | W10: 35703 | X10: 2.3465198 | Y10: =IF(ISNUMBER(H10),X10-H10,"") -> -0.053682862 | Z10: =IF(ISNUMBER(F10),F10+F10/$H10*$Y10,"") -> 1.6890381 | AA10: =IF(ISNUMBER(G10),G10+G10/$H10*$Y10,"") -> 0.65748172 | AB10: =IF(ISNUMBER(Z10),SUM(Z10:AA10)-X10,"") -> 0 | AC10: =IF(ISNUMBER(Z10),Z10/Goods!EH21,"") -> 2.1601952 | AD10: =IF(ISNUMBER(AA10),AA10/Services!EH21,"") -> 3.0144696
A11: =IF(MONTH(C11)=3,YEAR(C11),"") | B11: =CONCATENATE("Q",IF(MONTH(C11)=3,"1",IF(MONTH(C11)=6,"2",IF(MONTH(C11)=9,"3",IF(MONTH(C11)=12,"4",NA()))))) -> Q4 | C11: =Goods!B22 -> 35795 | D11: =Goods!FL22 -> 1.4089199 | E11: =Services!FL22 -> -0.15523429 | F11: =Goods!EI22 -> 1.0981826 | G11: =Services!EI22 -> -0.034236923 | H11: =SUM(F11:G11) -> 1.0639457 | K11: Q2 | L11: =F121 -> -0.68978582 | M11: =G121 -> 0.17851715 | N11: =H121 -> -0.51126866 | Q11: =Z121 -> -0.84885666 | R11: =AA121 -> 0.21968482 | S11: =X121 -> -0.62917184 | W11: 35795 | X11: 1.1666615 | Y11: =IF(ISNUMBER(H11),X11-H11,"") -> 0.10271583 | Z11: =IF(ISNUMBER(F11),F11+F11/$H11*$Y11,"") -> 1.2042038 | AA11: =IF(ISNUMBER(G11),G11+G11/$H11*$Y11,"") -> -0.037542236 | AB11: =IF(ISNUMBER(Z11),SUM(Z11:AA11)-X11,"") -> 2.220446e-16 | AC11: =IF(ISNUMBER(Z11),Z11/Goods!EH22,"") -> 1.5449404 | AD11: =IF(ISNUMBER(AA11),AA11/Services!EH22,"") -> -0.17022097
A12: =IF(MONTH(C12)=3,YEAR(C12),"") -> 1998 | B12: =CONCATENATE("Q",IF(MONTH(C12)=3,"1",IF(MONTH(C12)=6,"2",IF(MONTH(C12)=9,"3",IF(MONTH(C12)=12,"4",NA()))))) -> Q1 | C12: =Goods!B23 -> 35885 | D12: =Goods!FL23 -> 1.0620572 | E12: =Services!FL23 -> 1.8201055 | F12: =Goods!EI23 -> 0.83130633 | G12: =Services!EI23 -> 0.39545038 | H12: =SUM(F12:G12) -> 1.2267567 | K12: Q3 | L12: =0.34*0.8 -> 0.272 | M12: =4.41*0.2 -> 0.882 | N12: =M12+L12 -> 1.154 | O12: UNCTAD nowcast | Q12: =0.34*0.8 -> 0.272 | R12: =4.41*0.2 -> 0.882 | S12: =R12+Q12 -> 1.154 | T12: UNCTAD nowcast | W12: 35885 | X12: 0.51729061 | Y12: =IF(ISNUMBER(H12),X12-H12,"") -> -0.70946611 | Z12: =IF(ISNUMBER(F12),F12+F12/$H12*$Y12,"") -> 0.35053972 | AA12: =IF(ISNUMBER(G12),G12+G12/$H12*$Y12,"") -> 0.16675089 | AB12: =IF(ISNUMBER(Z12),SUM(Z12:AA12)-X12,"") -> 1.110223e-16 | AC12: =IF(ISNUMBER(Z12),Z12/Goods!EH23,"") -> 0.44784121 | AD12: =IF(ISNUMBER(AA12),AA12/Services!EH23,"") -> 0.76748998
A13: =IF(MONTH(C13)=3,YEAR(C13),"") | B13: =CONCATENATE("Q",IF(MONTH(C13)=3,"1",IF(MONTH(C13)=6,"2",IF(MONTH(C13)=9,"3",IF(MONTH(C13)=12,"4",NA()))))) -> Q2 | C13: =Goods!B24 -> 35976 | D13: =Goods!FL24 -> 0.27168603 | E13: =Services!FL24 -> 1.4289128 | F13: =Goods!EI24 -> 0.21224547 | G13: =Services!EI24 -> 0.3126233 | H13: =SUM(F13:G13) -> 0.52486876 | W13: 35976 | X13: -0.31519484 | Y13: =IF(ISNUMBER(H13),X13-H13,"") -> -0.8400636 | Z13: =IF(ISNUMBER(F13),F13+F13/$H13*$Y13,"") -> -0.12745791 | AA13: =IF(ISNUMBER(G13),G13+G13/$H13*$Y13,"") -> -0.18773693 | AB13: =IF(ISNUMBER(Z13),SUM(Z13:AA13)-X13,"") -> 5.5511151e-17 | AC13: =IF(ISNUMBER(Z13),Z13/Goods!EH24,"") -> -0.16315323 | AD13: =IF(ISNUMBER(AA13),AA13/Services!EH24,"") -> -0.85809251
A14: =IF(MONTH(C14)=3,YEAR(C14),"") | B14: =CONCATENATE("Q",IF(MONTH(C14)=3,"1",IF(MONTH(C14)=6,"2",IF(MONTH(C14)=9,"3",IF(MONTH(C14)=12,"4",NA()))))) -> Q3 | C14: =Goods!B25 -> 36068 | D14: =Goods!FL25 -> -0.17336062 | E14: =Services!FL25 -> 0.77330802 | F14: =Goods!EI25 -> -0.13503544 | G14: =Services!EI25 -> 0.17095675 | H14: =SUM(F14:G14) -> 0.035921307 | W14: 36068 | X14: -0.42476418 | Y14: =IF(ISNUMBER(H14),X14-H14,"") -> -0.46068549 | Z14: =IF(ISNUMBER(F14),F14+F14/$H14*$Y14,"") -> 1.5967743 | AA14: =IF(ISNUMBER(G14),G14+G14/$H14*$Y14,"") -> -2.0215384 | AB14: =IF(ISNUMBER(Z14),SUM(Z14:AA14)-X14,"") -> 0 | AC14: =IF(ISNUMBER(Z14),Z14/Goods!EH25,"") -> 2.0499639 | AD14: =IF(ISNUMBER(AA14),AA14/Services!EH25,"") -> -9.1442536
A15: =IF(MONTH(C15)=3,YEAR(C15),"") | B15: =CONCATENATE("Q",IF(MONTH(C15)=3,"1",IF(MONTH(C15)=6,"2",IF(MONTH(C15)=9,"3",IF(MONTH(C15)=12,"4",NA()))))) -> Q4 | C15: =Goods!B26 -> 36160 | D15: =Goods!FL26 -> 1.9465891 | E15: =Services!FL26 -> 0.59611956 | F15: =Goods!EI26 -> 1.5131523 | G15: =Services!EI26 -> 0.13273482 | H15: =SUM(F15:G15) -> 1.6458871 | W15: 36160 | X15: -0.55200746 | Y15: =IF(ISNUMBER(H15),X15-H15,"") -> -2.1978946 | Z15: =IF(ISNUMBER(F15),F15+F15/$H15*$Y15,"") -> -0.50749007 | AA15: =IF(ISNUMBER(G15),G15+G15/$H15*$Y15,"") -> -0.044517398 | AB15: =IF(ISNUMBER(Z15),SUM(Z15:AA15)-X15,"") -> -2.220446e-16 | AC15: =IF(ISNUMBER(Z15),Z15/Goods!EH26,"") -> -0.65285869 | AD15: =IF(ISNUMBER(AA15),AA15/Services!EH26,"") -> -0.19993014
A16: =IF(MONTH(C16)=3,YEAR(C16),"") -> 1999 | B16: =CONCATENATE("Q",IF(MONTH(C16)=3,"1",IF(MONTH(C16)=6,"2",IF(MONTH(C16)=9,"3",IF(MONTH(C16)=12,"4",NA()))))) -> Q1 | C16: =Goods!B27 -> 36250 | D16: =Goods!FL27 -> 2.1940681 | E16: =Services!FL27 -> 1.9203329 | F16: =Goods!EI27 -> 1.7120541 | G16: =Services!EI27 -> 0.42187728 | H16: =SUM(F16:G16) -> 2.1339313 | W16: 36250 | X16: 1.6410024 | Y16: =IF(ISNUMBER(H16),X16-H16,"") -> -0.49292891 | Z16: =IF(ISNUMBER(F16),F16+F16/$H16*$Y16,"") -> 1.316577 | AA16: =IF(ISNUMBER(G16),G16+G16/$H16*$Y16,"") -> 0.32442545 | AB16: =IF(ISNUMBER(Z16),SUM(Z16:AA16)-X16,"") -> 2.220446e-16 | AC16: =IF(ISNUMBER(Z16),Z16/Goods!EH27,"") -> 1.6872479 | AD16: =IF(ISNUMBER(AA16),AA16/Services!EH27,"") -> 1.4767443
A17: =IF(MONTH(C17)=3,YEAR(C17),"") | B17: =CONCATENATE("Q",IF(MONTH(C17)=3,"1",IF(MONTH(C17)=6,"2",IF(MONTH(C17)=9,"3",IF(MONTH(C17)=12,"4",NA()))))) -> Q2 | C17: =Goods!B28 -> 36341 | D17: =Goods!FL28 -> 2.9915705 | E17: =Services!FL28 -> 1.5508337 | F17: =Goods!EI28 -> 2.3356968 | G17: =Services!EI28 -> 0.34000572 | H17: =SUM(F17:G17) -> 2.6757025 | W17: 36341 | X17: 2.4695944 | Y17: =IF(ISNUMBER(H17),X17-H17,"") -> -0.20610809 | Z17: =IF(ISNUMBER(F17),F17+F17/$H17*$Y17,"") -> 2.1557792 | AA17: =IF(ISNUMBER(G17),G17+G17/$H17*$Y17,"") -> 0.31381524 | AB17: =IF(ISNUMBER(Z17),SUM(Z17:AA17)-X17,"") -> 0 | AC17: =IF(ISNUMBER(Z17),Z17/Goods!EH28,"") -> 2.7611313 | AD17: =IF(ISNUMBER(AA17),AA17/Services!EH28,"") -> 1.4313737
A18: =IF(MONTH(C18)=3,YEAR(C18),"") | B18: =CONCATENATE("Q",IF(MONTH(C18)=3,"1",IF(MONTH(C18)=6,"2",IF(MONTH(C18)=9,"3",IF(MONTH(C18)=12,"4",NA()))))) -> Q3 | C18: =Goods!B29 -> 36433 | D18: =Goods!FL29 -> 3.567367 | E18: =Services!FL29 -> 1.6645657 | F18: =Goods!EI29 -> 2.7923834 | G18: =Services!EI29 -> 0.36161435 | H18: =SUM(F18:G18) -> 3.1539977 | J18: RAW | O18: RESCALED | W18: 36433 | X18: 2.9701157 | Y18: =IF(ISNUMBER(H18),X18-H18,"") -> -0.18388201 | Z18: =IF(ISNUMBER(F18),F18+F18/$H18*$Y18,"") -> 2.6295839 | AA18: =IF(ISNUMBER(G18),G18+G18/$H18*$Y18,"") -> 0.34053178 | AB18: =IF(ISNUMBER(Z18),SUM(Z18:AA18)-X18,"") -> 0 | AC18: =IF(ISNUMBER(Z18),Z18/Goods!EH29,"") -> 3.359385 | AD18: =IF(ISNUMBER(AA18),AA18/Services!EH29,"") -> 1.5675195
A19: =IF(MONTH(C19)=3,YEAR(C19),"") | B19: =CONCATENATE("Q",IF(MONTH(C19)=3,"1",IF(MONTH(C19)=6,"2",IF(MONTH(C19)=9,"3",IF(MONTH(C19)=12,"4",NA()))))) -> Q4 | C19: =Goods!B30 -> 36525 | D19: =Goods!FL30 -> 3.5170877 | E19: =Services!FL30 -> 2.235111 | F19: =Goods!EI30 -> 2.7641015 | G19: =Services!EI30 -> 0.47852314 | H19: =SUM(F19:G19) -> 3.2426246 | W19: 36525 | X19: 3.3028324 | Y19: =IF(ISNUMBER(H19),X19-H19,"") -> 0.060207747 | Z19: =IF(ISNUMBER(F19),F19+F19/$H19*$Y19,"") -> 2.8154242 | AA19: =IF(ISNUMBER(G19),G19+G19/$H19*$Y19,"") -> 0.48740817 | AB19: =IF(ISNUMBER(Z19),SUM(Z19:AA19)-X19,"") -> 0 | AC19: =IF(ISNUMBER(Z19),Z19/Goods!EH30,"") -> 3.5823916 | AD19: =IF(ISNUMBER(AA19),AA19/Services!EH30,"") -> 2.2766116
A20: =IF(MONTH(C20)=3,YEAR(C20),"") -> 2000 | B20: =CONCATENATE("Q",IF(MONTH(C20)=3,"1",IF(MONTH(C20)=6,"2",IF(MONTH(C20)=9,"3",IF(MONTH(C20)=12,"4",NA()))))) -> Q1 | C20: =Goods!B31 -> 36616 | D20: =Goods!FL31 -> 4.1465463 | E20: =Services!FL31 -> 2.1840837 | F20: =Goods!EI31 -> 3.2744521 | G20: =Services!EI31 -> 0.45935259 | H20: =SUM(F20:G20) -> 3.7338046 | W20: 36616 | X20: 4.0552099 | Y20: =IF(ISNUMBER(H20),X20-H20,"") -> 0.32140529 | Z20: =IF(ISNUMBER(F20),F20+F20/$H20*$Y20,"") -> 3.5563163 | AA20: =IF(ISNUMBER(G20),G20+G20/$H20*$Y20,"") -> 0.49889359 | AB20: =IF(ISNUMBER(Z20),SUM(Z20:AA20)-X20,"") -> 0 | AC20: =IF(ISNUMBER(Z20),Z20/Goods!EH31,"") -> 4.5034803 | AD20: =IF(ISNUMBER(AA20),AA20/Services!EH31,"") -> 2.3720893
A21: =IF(MONTH(C21)=3,YEAR(C21),"") | B21: =CONCATENATE("Q",IF(MONTH(C21)=3,"1",IF(MONTH(C21)=6,"2",IF(MONTH(C21)=9,"3",IF(MONTH(C21)=12,"4",NA()))))) -> Q2 | C21: =Goods!B32 -> 36707 | D21: =Goods!FL32 -> 3.0353515 | E21: =Services!FL32 -> 3.0025363 | F21: =Goods!EI32 -> 2.4056593 | G21: =Services!EI32 -> 0.62288456 | H21: =SUM(F21:G21) -> 3.0285439 | W21: 36707 | X21: 2.9828977 | Y21: =IF(ISNUMBER(H21),X21-H21,"") -> -0.045646183 | Z21: =IF(ISNUMBER(F21),F21+F21/$H21*$Y21,"") -> 2.3694012 | AA21: =IF(ISNUMBER(G21),G21+G21/$H21*$Y21,"") -> 0.61349645 | AB21: =IF(ISNUMBER(Z21),SUM(Z21:AA21)-X21,"") -> 0 | AC21: =IF(ISNUMBER(Z21),Z21/Goods!EH32,"") -> 2.9896027 | AD21: =IF(ISNUMBER(AA21),AA21/Services!EH32,"") -> 2.9572821
A22: =IF(MONTH(C22)=3,YEAR(C22),"") | B22: =CONCATENATE("Q",IF(MONTH(C22)=3,"1",IF(MONTH(C22)=6,"2",IF(MONTH(C22)=9,"3",IF(MONTH(C22)=12,"4",NA()))))) -> Q3 | C22: =Goods!B33 -> 36799 | D22: =Goods!FL33 -> 3.677857 | E22: =Services!FL33 -> 2.0515442 | F22: =Goods!EI33 -> 2.9148151 | G22: =Services!EI33 -> 0.42563217 | H22: =SUM(F22:G22) -> 3.3404472 | W22: 36799 | X22: 3.3422315 | Y22: =IF(ISNUMBER(H22),X22-H22,"") -> 0.0017843235 | Z22: =IF(ISNUMBER(F22),F22+F22/$H22*$Y22,"") -> 2.916372 | AA22: =IF(ISNUMBER(G22),G22+G22/$H22*$Y22,"") -> 0.42585953 | AB22: =IF(ISNUMBER(Z22),SUM(Z22:AA22)-X22,"") -> 0 | AC22: =IF(ISNUMBER(Z22),Z22/Goods!EH33,"") -> 3.6798215 | AD22: =IF(ISNUMBER(AA22),AA22/Services!EH33,"") -> 2.0526401
A23: =IF(MONTH(C23)=3,YEAR(C23),"") | B23: =CONCATENATE("Q",IF(MONTH(C23)=3,"1",IF(MONTH(C23)=6,"2",IF(MONTH(C23)=9,"3",IF(MONTH(C23)=12,"4",NA()))))) -> Q4 | C23: =Goods!B34 -> 36891 | D23: =Goods!FL34 -> 1.3044358 | E23: =Services!FL34 -> 1.1675364 | F23: =Goods!EI34 -> 1.0366284 | G23: =Services!EI34 -> 0.23970125 | H23: =SUM(F23:G23) -> 1.2763297 | W23: 36891 | X23: 1.2199999 | Y23: =IF(ISNUMBER(H23),X23-H23,"") -> -0.056329812 | Z23: =IF(ISNUMBER(F23),F23+F23/$H23*$Y23,"") -> 0.99087766 | AA23: =IF(ISNUMBER(G23),G23+G23/$H23*$Y23,"") -> 0.22912222 | AB23: =IF(ISNUMBER(Z23),SUM(Z23:AA23)-X23,"") -> 0 | AC23: =IF(ISNUMBER(Z23),Z23/Goods!EH34,"") -> 1.2468656 | AD23: =IF(ISNUMBER(AA23),AA23/Services!EH34,"") -> 1.1160081
A24: =IF(MONTH(C24)=3,YEAR(C24),"") -> 2001 | B24: =CONCATENATE("Q",IF(MONTH(C24)=3,"1",IF(MONTH(C24)=6,"2",IF(MONTH(C24)=9,"3",IF(MONTH(C24)=12,"4",NA()))))) -> Q1 | C24: =Goods!B35 -> 36981 | D24: =Goods!FL35 -> -1.636072 | E24: =Services!FL35 -> 0.71171564 | F24: =Goods!EI35 -> -1.3001747 | G24: =Services!EI35 -> 0.14612031 | H24: =SUM(F24:G24) -> -1.1540544 | W24: 36981 | X24: -0.99706932 | Y24: =IF(ISNUMBER(H24),X24-H24,"") -> 0.15698512 | Z24: =IF(ISNUMBER(F24),F24+F24/$H24*$Y24,"") -> -1.123313 | AA24: =IF(ISNUMBER(G24),G24+G24/$H24*$Y24,"") -> 0.12624368 | AB24: =IF(ISNUMBER(Z24),SUM(Z24:AA24)-X24,"") -> 0 | AC24: =IF(ISNUMBER(Z24),Z24/Goods!EH35,"") -> -1.4135184 | AD24: =IF(ISNUMBER(AA24),AA24/Services!EH35,"") -> 0.61490152
A25: =IF(MONTH(C25)=3,YEAR(C25),"") | B25: =CONCATENATE("Q",IF(MONTH(C25)=3,"1",IF(MONTH(C25)=6,"2",IF(MONTH(C25)=9,"3",IF(MONTH(C25)=12,"4",NA()))))) -> Q2 | C25: =Goods!B36 -> 37072 | D25: =Goods!FL36 -> -2.921356 | E25: =Services!FL36 -> 0.83151041 | F25: =Goods!EI36 -> -2.3117452 | G25: =Services!EI36 -> 0.17351452 | H25: =SUM(F25:G25) -> -2.1382307 | W25: 37072 | X25: -1.8038027 | Y25: =IF(ISNUMBER(H25),X25-H25,"") -> 0.33442803 | Z25: =IF(ISNUMBER(F25),F25+F25/$H25*$Y25,"") -> -1.9501788 | AA25: =IF(ISNUMBER(G25),G25+G25/$H25*$Y25,"") -> 0.14637614 | AB25: =IF(ISNUMBER(Z25),SUM(Z25:AA25)-X25,"") -> 0 | AC25: =IF(ISNUMBER(Z25),Z25/Goods!EH36,"") -> -2.4644439 | AD25: =IF(ISNUMBER(AA25),AA25/Services!EH36,"") -> 0.70145878
A26: =IF(MONTH(C26)=3,YEAR(C26),"") | B26: =CONCATENATE("Q",IF(MONTH(C26)=3,"1",IF(MONTH(C26)=6,"2",IF(MONTH(C26)=9,"3",IF(MONTH(C26)=12,"4",NA()))))) -> Q3 | C26: =Goods!B37 -> 37164 | D26: =Goods!FL37 -> -2.4307043 | E26: =Services!FL37 -> -2.00993 | F26: =Goods!EI37 -> -1.9083759 | G26: =Services!EI37 -> -0.43190917 | H26: =SUM(F26:G26) -> -2.3402851 | W26: 37164 | X26: -1.9884876 | Y26: =IF(ISNUMBER(H26),X26-H26,"") -> 0.35179744 | Z26: =IF(ISNUMBER(F26),F26+F26/$H26*$Y26,"") -> -1.6215041 | AA26: =IF(ISNUMBER(G26),G26+G26/$H26*$Y26,"") -> -0.36698351 | AB26: =IF(ISNUMBER(Z26),SUM(Z26:AA26)-X26,"") -> 2.220446e-16 | AC26: =IF(ISNUMBER(Z26),Z26/Goods!EH37,"") -> -2.0653148 | AD26: =IF(ISNUMBER(AA26),AA26/Services!EH37,"") -> -1.7077923
A27: =IF(MONTH(C27)=3,YEAR(C27),"") | B27: =CONCATENATE("Q",IF(MONTH(C27)=3,"1",IF(MONTH(C27)=6,"2",IF(MONTH(C27)=9,"3",IF(MONTH(C27)=12,"4",NA()))))) -> Q4 | C27: =Goods!B38 -> 37256 | D27: =Goods!FL38 -> -0.58462971 | E27: =Services!FL38 -> -2.4578944 | F27: =Goods!EI38 -> -0.45856387 | G27: =Services!EI38 -> -0.53000474 | H27: =SUM(F27:G27) -> -0.98856862 | W27: 37256 | X27: -0.73512787 | Y27: =IF(ISNUMBER(H27),X27-H27,"") -> 0.25344075 | Z27: =IF(ISNUMBER(F27),F27+F27/$H27*$Y27,"") -> -0.3410012 | AA27: =IF(ISNUMBER(G27),G27+G27/$H27*$Y27,"") -> -0.39412667 | AB27: =IF(ISNUMBER(Z27),SUM(Z27:AA27)-X27,"") -> 0 | AC27: =IF(ISNUMBER(Z27),Z27/Goods!EH38,"") -> -0.43474736 | AD27: =IF(ISNUMBER(AA27),AA27/Services!EH38,"") -> -1.8277605
A28: =IF(MONTH(C28)=3,YEAR(C28),"") -> 2002 | B28: =CONCATENATE("Q",IF(MONTH(C28)=3,"1",IF(MONTH(C28)=6,"2",IF(MONTH(C28)=9,"3",IF(MONTH(C28)=12,"4",NA()))))) -> Q1 | C28: =Goods!B39 -> 37346 | D28: =Goods!FL39 -> 2.0165109 | E28: =Services!FL39 -> 5.1309855 | F28: =Goods!EI39 -> 1.5866879 | G28: =Services!EI39 -> 1.0936789 | H28: =SUM(F28:G28) -> 2.6803668 | W28: 37346 | X28: 2.8748211 | Y28: =IF(ISNUMBER(H28),X28-H28,"") -> 0.1944543 | Z28: =IF(ISNUMBER(F28),F28+F28/$H28*$Y28,"") -> 1.7017984 | AA28: =IF(ISNUMBER(G28),G28+G28/$H28*$Y28,"") -> 1.1730228 | AB28: =IF(ISNUMBER(Z28),SUM(Z28:AA28)-X28,"") -> 0 | AC28: =IF(ISNUMBER(Z28),Z28/Goods!EH39,"") -> 2.162804 | AD28: =IF(ISNUMBER(AA28),AA28/Services!EH39,"") -> 5.5032264
A29: =IF(MONTH(C29)=3,YEAR(C29),"") | B29: =CONCATENATE("Q",IF(MONTH(C29)=3,"1",IF(MONTH(C29)=6,"2",IF(MONTH(C29)=9,"3",IF(MONTH(C29)=12,"4",NA()))))) -> Q2 | C29: =Goods!B40 -> 37437 | D29: =Goods!FL40 -> 4.3978941 | E29: =Services!FL40 -> 1.2024999 | F29: =Goods!EI40 -> 3.4389971 | G29: =Services!EI40 -> 0.26218766 | H29: =SUM(F29:G29) -> 3.7011848 | W29: 37437 | X29: 3.4340059 | Y29: =IF(ISNUMBER(H29),X29-H29,"") -> -0.26717889 | Z29: =IF(ISNUMBER(F29),F29+F29/$H29*$Y29,"") -> 3.1907449 | AA29: =IF(ISNUMBER(G29),G29+G29/$H29*$Y29,"") -> 0.24326102 | AB29: =IF(ISNUMBER(Z29),SUM(Z29:AA29)-X29,"") -> 0 | AC29: =IF(ISNUMBER(Z29),Z29/Goods!EH40,"") -> 4.0804216 | AD29: =IF(ISNUMBER(AA29),AA29/Services!EH40,"") -> 1.1156946
A30: =IF(MONTH(C30)=3,YEAR(C30),"") | B30: =CONCATENATE("Q",IF(MONTH(C30)=3,"1",IF(MONTH(C30)=6,"2",IF(MONTH(C30)=9,"3",IF(MONTH(C30)=12,"4",NA()))))) -> Q3 | C30: =Goods!B41 -> 37529 | D30: =Goods!FL41 -> 1.9939523 | E30: =Services!FL41 -> -0.13807316 | F30: =Goods!EI41 -> 1.5688266 | G30: =Services!EI41 -> -0.029438238 | H30: =SUM(F30:G30) -> 1.5393884 | W30: 37529 | X30: 1.7846762 | Y30: =IF(ISNUMBER(H30),X30-H30,"") -> 0.24528783 | Z30: =IF(ISNUMBER(F30),F30+F30/$H30*$Y30,"") -> 1.8188052 | AA30: =IF(ISNUMBER(G30),G30+G30/$H30*$Y30,"") -> -0.034128959 | AB30: =IF(ISNUMBER(Z30),SUM(Z30:AA30)-X30,"") -> 0 | AC30: =IF(ISNUMBER(Z30),Z30/Goods!EH41,"") -> 2.3116708 | AD30: =IF(ISNUMBER(AA30),AA30/Services!EH41,"") -> -0.16007389
... A59: =IF(MONTH(C59)=3,YEAR(C59),"") | B59: =CONCATENATE("Q",IF(MONTH(C59)=3,"1",IF(MONTH(C59)=6,"2",IF(MONTH(C59)=9,"3",IF(MONTH(C59)=12,"4",NA()))))) -> Q4 | C59: =Goods!B70 -> 40178 | D59: =Goods!FL70 -> 4.898386 | E59: =Services!FL70 -> 1.9131469 | F59: =Goods!EI70 -> 3.816506 | G59: =Services!EI70 -> 0.42254641 | H59: =SUM(F59:G59) -> 4.2390524 | W59: 40178 | X59: 4.5331456 | Y59: =IF(ISNUMBER(H59),X59-H59,"") -> 0.29409321 | Z59: =IF(ISNUMBER(F59),F59+F59/$H59*$Y59,"") -> 4.0812841 | AA59: =IF(ISNUMBER(G59),G59+G59/$H59*$Y59,"") -> 0.45186146 | AB59: =IF(ISNUMBER(Z59),SUM(Z59:AA59)-X59,"") -> 0 | AC59: =IF(ISNUMBER(Z59),Z59/Goods!EH70,"") -> 5.2382218 | AD59: =IF(ISNUMBER(AA59),AA59/Services!EH70,"") -> 2.0458755
A60: 24 | B60: =CONCATENATE("Q",IF(MONTH(C60)=3,"1",IF(MONTH(C60)=6,"2",IF(MONTH(C60)=9,"3",IF(MONTH(C60)=12,"4",NA()))))) -> Q1 | C60: =Goods!B71 -> 40268 | D60: =Goods!FL71 -> 3.6215887 | E60: =Services!FL71 -> 1.5956458 | F60: =Goods!EI71 -> 2.843434 | G60: =Services!EI71 -> 0.34284936 | H60: =SUM(F60:G60) -> 3.1862833 | W60: 40268 | X60: 3.2949296 | Y60: =IF(ISNUMBER(H60),X60-H60,"") -> 0.10864631 | Z60: =IF(ISNUMBER(F60),F60+F60/$H60*$Y60,"") -> 2.9403897 | AA60: =IF(ISNUMBER(G60),G60+G60/$H60*$Y60,"") -> 0.35453988 | AB60: =IF(ISNUMBER(Z60),SUM(Z60:AA60)-X60,"") -> 0 | AC60: =IF(ISNUMBER(Z60),Z60/Goods!EH71,"") -> 3.7450781 | AD60: =IF(ISNUMBER(AA60),AA60/Services!EH71,"") -> 1.6500544
A61: =IF(MONTH(C61)=3,YEAR(C61),"") | B61: =CONCATENATE("Q",IF(MONTH(C61)=3,"1",IF(MONTH(C61)=6,"2",IF(MONTH(C61)=9,"3",IF(MONTH(C61)=12,"4",NA()))))) -> Q2 | C61: =Goods!B72 -> 40359 | D61: =Goods!FL72 -> 4.6656164 | E61: =Services!FL72 -> 2.0159362 | F61: =Goods!EI72 -> 3.6771521 | G61: =Services!EI72 -> 0.42709921 | H61: =SUM(F61:G61) -> 4.1042513 | W61: 40359 | X61: 4.3701742 | Y61: =IF(ISNUMBER(H61),X61-H61,"") -> 0.26592294 | Z61: =IF(ISNUMBER(F61),F61+F61/$H61*$Y61,"") -> 3.9154024 | AA61: =IF(ISNUMBER(G61),G61+G61/$H61*$Y61,"") -> 0.45477185 | AB61: =IF(ISNUMBER(Z61),SUM(Z61:AA61)-X61,"") -> 0 | AC61: =IF(ISNUMBER(Z61),Z61/Goods!EH72,"") -> 4.9679114 | AD61: =IF(ISNUMBER(AA61),AA61/Services!EH72,"") -> 2.1465529
A62: =IF(MONTH(C62)=3,YEAR(C62),"") | B62: =CONCATENATE("Q",IF(MONTH(C62)=3,"1",IF(MONTH(C62)=6,"2",IF(MONTH(C62)=9,"3",IF(MONTH(C62)=12,"4",NA()))))) -> Q3 | C62: =Goods!B73 -> 40451 | D62: =Goods!FL73 -> 2.440693 | E62: =Services!FL73 -> 1.3090864 | F62: =Goods!EI73 -> 1.9338053 | G62: =Services!EI73 -> 0.27187353 | H62: =SUM(F62:G62) -> 2.2056788 | W62: 40451 | X62: 2.6230265 | Y62: =IF(ISNUMBER(H62),X62-H62,"") -> 0.41734763 | Z62: =IF(ISNUMBER(F62),F62+F62/$H62*$Y62,"") -> 2.2997104 | AA62: =IF(ISNUMBER(G62),G62+G62/$H62*$Y62,"") -> 0.32331609 | AB62: =IF(ISNUMBER(Z62),SUM(Z62:AA62)-X62,"") -> 0 | AC62: =IF(ISNUMBER(Z62),Z62/Goods!EH73,"") -> 2.9025088 | AD62: =IF(ISNUMBER(AA62),AA62/Services!EH73,"") -> 1.5567853
A63: =IF(MONTH(C63)=3,YEAR(C63),"") | B63: =CONCATENATE("Q",IF(MONTH(C63)=3,"1",IF(MONTH(C63)=6,"2",IF(MONTH(C63)=9,"3",IF(MONTH(C63)=12,"4",NA()))))) -> Q4 | C63: =Goods!B74 -> 40543 | D63: =Goods!FL74 -> 1.5222112 | E63: =Services!FL74 -> 1.0813377 | F63: =Goods!EI74 -> 1.2087283 | G63: =Services!EI74 -> 0.2226898 | H63: =SUM(F63:G63) -> 1.4314181 | W63: 40543 | X63: 1.9491711 | Y63: =IF(ISNUMBER(H63),X63-H63,"") -> 0.51775307 | Z63: =IF(ISNUMBER(F63),F63+F63/$H63*$Y63,"") -> 1.645933 | AA63: =IF(ISNUMBER(G63),G63+G63/$H63*$Y63,"") -> 0.30323813 | AB63: =IF(ISNUMBER(Z63),SUM(Z63:AA63)-X63,"") -> -2.220446e-16 | AC63: =IF(ISNUMBER(Z63),Z63/Goods!EH74,"") -> 2.0728047 | AD63: =IF(ISNUMBER(AA63),AA63/Services!EH74,"") -> 1.4724645
A64: =IF(MONTH(C64)=3,YEAR(C64),"") -> 2011 | B64: =CONCATENATE("Q",IF(MONTH(C64)=3,"1",IF(MONTH(C64)=6,"2",IF(MONTH(C64)=9,"3",IF(MONTH(C64)=12,"4",NA()))))) -> Q1 | C64: =Goods!B75 -> 40633 | D64: =Goods!FL75 -> 2.5390905 | E64: =Services!FL75 -> -0.09889068 | F64: =Goods!EI75 -> 2.0173606 | G64: =Services!EI75 -> -0.020319963 | H64: =SUM(F64:G64) -> 1.9970406 | W64: 40633 | X64: 1.909364 | Y64: =IF(ISNUMBER(H64),X64-H64,"") -> -0.087676583 | Z64: =IF(ISNUMBER(F64),F64+F64/$H64*$Y64,"") -> 1.9287919 | AA64: =IF(ISNUMBER(G64),G64+G64/$H64*$Y64,"") -> -0.01942785 | AB64: =IF(ISNUMBER(Z64),SUM(Z64:AA64)-X64,"") -> 0 | AC64: =IF(ISNUMBER(Z64),Z64/Goods!EH75,"") -> 2.4276161 | AD64: =IF(ISNUMBER(AA64),AA64/Services!EH75,"") -> -0.094549057
A65: =IF(MONTH(C65)=3,YEAR(C65),"") | B65: =CONCATENATE("Q",IF(MONTH(C65)=3,"1",IF(MONTH(C65)=6,"2",IF(MONTH(C65)=9,"3",IF(MONTH(C65)=12,"4",NA()))))) -> Q2 | C65: =Goods!B76 -> 40724 | D65: =Goods!FL76 -> 0.7161215 | E65: =Services!FL76 -> 1.2381522 | F65: =Goods!EI76 -> 0.57178447 | G65: =Services!EI76 -> 0.24955433 | H65: =SUM(F65:G65) -> 0.8213388 | W65: 40724 | X65: 1.8408397 | Y65: =IF(ISNUMBER(H65),X65-H65,"") -> 1.0195009 | Z65: =IF(ISNUMBER(F65),F65+F65/$H65*$Y65,"") -> 1.2815218 | AA65: =IF(ISNUMBER(G65),G65+G65/$H65*$Y65,"") -> 0.55931795 | AB65: =IF(ISNUMBER(Z65),SUM(Z65:AA65)-X65,"") -> -2.220446e-16 | AC65: =IF(ISNUMBER(Z65),Z65/Goods!EH76,"") -> 1.6050197 | AD65: =IF(ISNUMBER(AA65),AA65/Services!EH76,"") -> 2.77503
A66: =IF(MONTH(C66)=3,YEAR(C66),"") | B66: =CONCATENATE("Q",IF(MONTH(C66)=3,"1",IF(MONTH(C66)=6,"2",IF(MONTH(C66)=9,"3",IF(MONTH(C66)=12,"4",NA()))))) -> Q3 | C66: =Goods!B77 -> 40816 | D66: =Goods!FL77 -> 1.1249233 | E66: =Services!FL77 -> 1.7577231 | F66: =Goods!EI77 -> 0.89735017 | G66: =Services!EI77 -> 0.35558913 | H66: =SUM(F66:G66) -> 1.2529393 | W66: 40816 | X66: 1.0892763 | Y66: =IF(ISNUMBER(H66),X66-H66,"") -> -0.16366304 | Z66: =IF(ISNUMBER(F66),F66+F66/$H66*$Y66,"") -> 0.78013535 | AA66: =IF(ISNUMBER(G66),G66+G66/$H66*$Y66,"") -> 0.30914091 | AB66: =IF(ISNUMBER(Z66),SUM(Z66:AA66)-X66,"") -> 0 | AC66: =IF(ISNUMBER(Z66),Z66/Goods!EH77,"") -> 0.9779821 | AD66: =IF(ISNUMBER(AA66),AA66/Services!EH77,"") -> 1.5281236
A67: =IF(MONTH(C67)=3,YEAR(C67),"") | B67: =CONCATENATE("Q",IF(MONTH(C67)=3,"1",IF(MONTH(C67)=6,"2",IF(MONTH(C67)=9,"3",IF(MONTH(C67)=12,"4",NA()))))) -> Q4 | C67: =Goods!B78 -> 40908 | D67: =Goods!FL78 -> 0.63803844 | E67: =Services!FL78 -> 0.97301342 | F67: =Goods!EI78 -> 0.5084341 | G67: =Services!EI78 -> 0.19764759 | H67: =SUM(F67:G67) -> 0.70608169 | W67: 40908 | X67: 1.1302778 | Y67: =IF(ISNUMBER(H67),X67-H67,"") -> 0.42419609 | Z67: =IF(ISNUMBER(F67),F67+F67/$H67*$Y67,"") -> 0.8138885 | AA67: =IF(ISNUMBER(G67),G67+G67/$H67*$Y67,"") -> 0.31638928 | AB67: =IF(ISNUMBER(Z67),SUM(Z67:AA67)-X67,"") -> 0 | AC67: =IF(ISNUMBER(Z67),Z67/Goods!EH78,"") -> 1.0213559 | AD67: =IF(ISNUMBER(AA67),AA67/Services!EH78,"") -> 1.5575754
A68: =IF(MONTH(C68)=3,YEAR(C68),"") -> 2012 | B68: =CONCATENATE("Q",IF(MONTH(C68)=3,"1",IF(MONTH(C68)=6,"2",IF(MONTH(C68)=9,"3",IF(MONTH(C68)=12,"4",NA()))))) -> Q1 | C68: =Goods!B79 -> 40999 | D68: =Goods!FL79 -> 1.31599 | E68: =Services!FL79 -> 1.8631423 | F68: =Goods!EI79 -> 1.0492074 | G68: =Services!EI79 -> 0.37770341 | H68: =SUM(F68:G68) -> 1.4269108 | W68: 40999 | X68: 1.349236 | Y68: =IF(ISNUMBER(H68),X68-H68,"") -> -0.077674844 | Z68: =IF(ISNUMBER(F68),F68+F68/$H68*$Y68,"") -> 0.99209308 | AA68: =IF(ISNUMBER(G68),G68+G68/$H68*$Y68,"") -> 0.35714287 | AB68: =IF(ISNUMBER(Z68),SUM(Z68:AA68)-X68,"") -> 0 | AC68: =IF(ISNUMBER(Z68),Z68/Goods!EH79,"") -> 1.2443532 | AD68: =IF(ISNUMBER(AA68),AA68/Services!EH79,"") -> 1.7617209
...

Sheet Goods
C1: US | D1: UK | E1: JP | F1: CA | G1: NZ | H1: AU | I1: TH | J1: CL | K1: MX | L1: BG | M1: CZ | N1: HU | O1: RO | P1: SE | Q1: DK | R1: NO | S1: CH | T1: PL | U1: HK | V1: KR | W1: SG | X1: TW | Y1: IN | Z1: MY | AA1: PH | AD1: US | AE1: UK | AF1: JP | AG1: CA | AH1: NZ | AI1: AU | AJ1: TH | AK1: CL | AL1: MX | AM1: BG | AN1: CZ | AO1: HU | AP1: RO | AQ1: SE | AR1: DK | AS1: NO | AT1: CH | AU1: PL | AV1: HK | AW1: KR | AX1: SG | AY1: TW | AZ1: IN | BA1: MY | BB1: PH | BE1: US | BF1: UK | BG1: JP | BH1: CA | BI1: NZ | BJ1: AU | BK1: TH | BL1: CL | BM1: MX | BN1: BG | BO1: CZ | BP1: HU | BQ1: RO | BR1: SE | BS1: DK | BT1: NO | BU1: CH | BV1: PL | BW1: HK | BX1: KR | BY1: SG | BZ1: TW | CA1: IN | CB1: MY | CC1: PH | CD1: COVERAGE | CG1: US | CH1: UK | CI1: JP | CJ1: CA | CK1: NZ | CL1: AU | CM1: TH | CN1: CL | CO1: MX | CP1: BG | CQ1: CZ | CR1: HU | CS1: RO | CT1: SE | CU1: DK | CV1: NO | CW1: CH | CX1: PL | CY1: HK | CZ1: KR | DA1: SG | DB1: TW | DC1: IN | DD1: MY | DE1: PH | DF1: Check | DG1: Global excl. EA | DI1: US | DJ1: UK | DK1: JP | DL1: CA | DM1: NZ | DN1: AU | DO1: TH | DP1: CL | DQ1: MX | DR1: BG | DS1: CZ | DT1: HU | DU1: RO | DV1: SE | DW1: DK | DX1: NO | DY1: CH | DZ1: PL | EA1: HK | EB1: KR | EC1: SG | ED1: TW | EE1: IN | EF1: MY | EG1: PH | EH1: Goods weight | EI1: Global excl. EA | EL1: US | EM1: UK | EN1: JP | EO1: CA | EP1: NZ | EQ1: AU | ER1: TH | ES1: CL | ET1: MX | EU1: BG | EV1: CZ | EW1: HU | EX1: RO | EY1: SE | EZ1: DK | FA1: NO | FB1: CH | FC1: PL | FD1: HK | FE1: KR | FF1: SG | FG1: TW | FH1: IN | FI1: MY | FJ1: PH | FK1: Check | FL1: Global excl. EA
A2: 961 !Q | B2: .excel_last | C2: MMH@USECON | D2: BQKOQ@UK | E2: RESIC2@JAPAN*1000 | F2: V6E05749@CANADA | G2: NZSNMGC@ANZ | H2: S193GMGR@IFS | I2: S578GMGR@IFS | J2: S228GMGR@IFS | K2: sa(C273GMGR@IFS) | L2: S918NMGC@EMERGECW/1000 | M2: S935NMGC@EMERGECW | N2: S944NMGC@EMERGECW*1000 | O2: S968NMGC@EMERGECW | P2: J144IMMU@EUDATA | Q2: DKSNMGC@NORDIC | R2: NOSNMGC@NORDIC | S2: CHSNMGC@ALPMED | T2: J964IMMT@EUNA | U2: S532NMGC@EMERGEPR | V2: S542NMGC@EMERGEPR | W2: S576NMGC@EMERGEPR | X2: SA(N528NMMC@EMERGEPR) | Y2: H536NMGC@EMERGEPR | Z2: H548NMGC@EMERGEPR | AA2: S566NMGC@EMERGEPR
A3: .DESC | C3: Real Imports of Goods (SAAR, Bil.Chn.2017$) | D3: UK: Imports: Goods (SA, Mil.Chn.2022.Pounds) | E3: Japan: Real GDP: Imports Of Goods (SAAR, Tril.Chn.2015.Yen) | F3: Canada: GDP: Imports: Goods (SAAR, Mil.Chn.2017.C$) | G3: New Zealand: GDP: Imports of Goods (SA, Mil.Chained.Q2:09-Q1:10.NZ$) | H3: Australia: Real Imports of Goods(SA, Mil.Chn.2018.A$) | I3: Thailand: Real Imports of Goods (SA, Mil.Chn.2002.Baht) | J3: Chile: Real Imports of Goods(SA, Mil.Chn.2018.Pesos) | K3: Mexico: Real Imports of Goods (NSA,Mil.2018 New Pesos) - Seasonal Adjustment, All | L3: Bulgaria: GDP: Imports of Goods (SWDA, Thous.Chn.2020.Leva) | M3: Czechia: GDP: Imports of Goods (SWDA, Mil.Chn.2020.CZK) | N3: Hungary: GDP: Imports of Goods (SA, Tril.Chn.2021.Forints) | O3: Romania: GDP: Imports of Goods (SWDA, Mil.Chn.2020.New Lei) | P3: Sweden: Imports of Goods (SWDA, Mil.Ch.20.EUR-ECU) | Q3: Denmark: GDP: Imports of Goods (SA, Mil.Chn.2020.DKK) | R3: Norway: GDP: Imports of Goods (SA, Mil.Chn.2022.Kroner) | S3: Switzerland: GDP: Imports of Goods (SA, Mil.Chn.2015.Francs) | T3: Poland: Imports of Goods (SWDA, Mil.Ch.2020.PLN) | U3: Hong Kong: GDP: Imports of Goods, fob (SA, Mil.Chn.2023.HK$) | V3: South Korea: GDP: Imports of Goods F.O.B. Basis (SA, Bil.Ch.2020.Won) | W3: Singapore: GDP: Imports of Goods (SA, Mil.Chn.2015.S$) | X3: Taiwan: GDP: Imports: Merchandise,Freight and Insurance (NSA, Mil.Chn.2021.NT$) - Seasonal Adjustment, All | Y3: Indonesia: GDP: Imports of Goods (SA, Bil.2010.Rupiahs) | Z3: Malaysia: GDP: Imports of Goods (SA, Mil.2015.Ringgit) | AA3: Philippines: GDP: Imports of Goods (SA, Mil.2018.Pesos) | AD3: Imports of goods q-o-q percentage changes | BE3: COUNTRY WEIGHTS | CD3: Coverage in World excl. EA trade | CG3: RESCALED COUNTRY WEIGHTS | DF3: Should be 1 | DG3: Contribution of goods in total imports | DI3: COUNTRY/SECTOR WEIGHTS | EH3: Weight of goods in total trade | EI3: Contribution of goods in total imports | EL3: RESCALED COUNTRY/SECTOR WEIGHTS | FK3: Should be 1 | FL3: Imports of goods
A4: .T1 | C4: Q1-1947 | D4: Q1-1955 | E4: Q1-1980 | F4: Q1-1961 | G4: Q2-1987 | H4: Q3-1971 | I4: Q1-2003 | J4: Q1-1996 | K4: Q1-1993 | L4: Q1-1995 | M4: Q1-1996 | N4: Q1-1995 | O4: Q1-1995 | P4: Q1-1993 | Q4: Q1-1991 | R4: Q2-1980 | S4: Q1-1980 | T4: Q1-1995 | U4: Q1-1990 | V4: Q1-1960 | W4: Q1-1986 | X4: Q1-1961 | Y4: Q1-2000 | Z4: Q1-2015 | AA4: Q1-2021 | DG4: q-o-q | EI4: q-o-q | FL4: q-o-q
A5: .TN | C5: Q2-2025 | D5: Q2-2025 | E5: Q2-2025 | F5: Q2-2025 | G5: Q1-2025 | H5: Q1-2025 | I5: Q2-2025 | J5: Q1-2025 | K5: Q1-2025 | L5: Q2-2025 | M5: Q2-2025 | N5: Q2-2025 | O5: Q2-2025 | P5: Q2-2025 | Q5: Q2-2025 | R5: Q2-2025 | S5: Q2-2025 | T5: Q2-2025 | U5: Q2-2025 | V5: Q2-2025 | W5: Q2-2025 | X5: Q2-2025 | Y5: Q2-2025 | Z5: Q2-2025 | AA5: Q2-2025
A6: .LSOURCE | C6: Bureau of Economic Analysis | D6: Office for National Statistics | E6: Cabinet Office of Japan | F6: Statistics Canada | G6: Stats NZ | H6: International Monetary Fund | I6: International Monetary Fund | J6: International Monetary Fund | K6: International Monetary Fund | L6: National Statistical Institute | M6: Czech Statistical Office | N6: Central Statistical Office | O6: Instit. National de Statistica si Studii Economice | P6: Statistical Office of the European Communities | Q6: Danmarks Statistik | R6: Statistiska Sentralbyra | S6: State Secretariat for Economic Affairs | T6: Statistical Office of the European Communities | U6: Census and Statistics Department | V6: Bank of Korea | W6: Department of Statistics | X6: Directorate-General of Budget Accounting & Stats | Y6: Badan Pusat Statistik/Haver Analytics | Z6: Department of Statistics, Malaysia/Haver Analytics | AA6: Philippine Statistics Authority
A7: .AGG | C7: Average | D7: Sum | E7: Average | F7: Average | G7: Sum | H7: Sum | I7: Sum | J7: Sum | K7: Sum | L7: Sum | M7: Sum | N7: Sum | O7: Sum | P7: Sum | Q7: Sum | R7: Sum | S7: Sum | T7: Sum | U7: Sum | V7: Sum | W7: Sum | X7: Sum | Y7: Sum | Z7: Sum | AA7: Sum
A8: .DTLM | C8: Aug-28-2025 14:31 | D8: Sep-12-2025 08:03 | E8: Sep-08-2025 01:54 | F8: Aug-29-2025 14:31 | G8: Jun-19-2025 00:47 | H8: Jun-23-2025 20:00 | I8: Aug-20-2025 16:04 | J8: Jun-23-2025 20:00 | K8: Jul-14-2025 19:00 | L8: Sep-05-2025 10:04 | M8: Aug-29-2025 09:06 | N8: Sep-02-2025 08:31 | O8: Sep-05-2025 08:10 | P8: Sep-01-2025 23:48 | Q8: Aug-20-2025 08:25 | R8: Aug-21-2025 08:03 | S8: Aug-28-2025 09:10 | T8: Sep-01-2025 23:48 | U8: Aug-15-2025 10:35 | V8: Sep-03-2025 01:05 | W8: Aug-12-2025 02:07 | X8: Aug-15-2025 10:53 | Y8: Aug-05-2025 06:27 | Z8: Aug-15-2025 06:14 | AA8: Aug-07-2025 04:07
A9: .FRQ | C9: Quarterly | D9: Quarterly | E9: Quarterly | F9: Quarterly | G9: Quarterly | H9: Quarterly | I9: Quarterly | J9: Quarterly | K9: Quarterly | L9: Quarterly | M9: Quarterly | N9: Quarterly | O9: Quarterly | P9: Quarterly | Q9: Quarterly | R9: Quarterly | S9: Quarterly | T9: Quarterly | U9: Quarterly | V9: Quarterly | W9: Quarterly | X9: Quarterly | Y9: Quarterly | Z9: Quarterly | AA9: Quarterly
A10: .DATA_TYPE | C10: US$ | D10: LocCur | E10: LocCur | F10: LocCur | G10: LocCur | H10: LocCur | I10: LocCur | J10: LocCur | K10: LocCur | L10: LocCur | M10: LocCur | N10: LocCur | O10: LocCur | P10: ? | Q10: LocCur | R10: LocCur | S10: LocCur | T10: LocCur | U10: LocCur | V10: LocCur | W10: LocCur | X10: LocCur | Y10: LocCur | Z10: LocCur | AA10: LocCur
A11: .MAG | C11: 9 | D11: 6 | E11: 12 <- 9 | F11: 6 | G11: 6 | H11: 6 | I11: 6 | J11: 6 | K11: 6 | L11: 3 | M11: 6 | N11: 12 <- 9 | O11: 6 | P11: 6 | Q11: 6 | R11: 6 | S11: 6 | T11: 6 | U11: 6 | V11: 9 | W11: 6 | X11: 6 | Y11: 9 | Z11: 6 | AA11: 6
A12: .GRP | C12: N02 | D12: P69 | E12: N13 | F12: N10 | G12: K16 | H12: A10 | I12: A10 | J12: L10 | K12: N10 | L12: B28 | M12: C20 | N12: H61 | O12: U20 | P12: E30 | Q12: D20 | R12: O20 | S12: C22 | T12: P47 | U12: D55 | V12: G61 | W12: J61 | X12: T19 | Y12: F62 | Z12: H61 | AA12: I50
A13: .GRPDESC | C13: Real Gross Domestic Product | D13: U.K.: National Accounts Detail, ONS, Quarterly | E13: Japan: National Accounts: Detailed Components, CAO | F13: Canada: Gross Domestic Product, StatCan, Quarterly | G13: New Zealand: Gross Domestic Product, SNZ, Quarterly | H13: Asia, Quarterly | I13: Asia, Quarterly | J13: Latin America, Quarterly | K13: North America, Quarterly | L13: Bulgaria: National Accounts, NSI, Quarterly | M13: Czech Republic: National Accounts, CSO, Quarterly | N13: Hungary: GDP Percent Changes, CSO, Quarterly | O13: Romania: National Accounts, INSSE, Quarterly | P13: EU: Harmonized National Accounts, Eurostat, Quarterly | Q13: Denmark: National Accounts, DSt, Quarterly | R13: Norway: National Accounts, SSb, Quarterly | S13: Switzerland: Real GDP, SECO, Quarterly | T13: Main National Accounts Aggregates, Eurostat, Quarterly | U13: Hong Kong: National Accounts, HKCSD, Quarterly | V13: Korea: GDP by Expenditure, BOK, Quarterly | W13: Singapore: National Accounts, DoS, Quarterly | X13: Taiwan: National Accounts, DGBASY, Quarterly | Y13: Indonesia: National Accounts, BPS/Haver, Quarterly | Z13: Malaysia: National Accounts, MDS/Haver, Quarterly | AA13: Philippines: National Accounts, PSA, Quarterly
A14: .GEO | C14: 111 | D14: 112 | E14: 158 | F14: 156 | G14: 196 | H14: 193 | I14: 578 | J14: 228 | K14: 273 | L14: 918 | M14: 935 | N14: 944 | O14: 968 | P14: 144 | Q14: 128 | R14: 142 | S14: 146 | T14: 964 | U14: 532 | V14: 542 | W14: 576 | X14: 528 | Y14: 536 | Z14: 548 | AA14: 566
A15: 961 | B15: 35155 | C15: 826.9 | D15: 59586 | E15: 40683.8 | F15: 250654 | G15: 5370 | H15: 22797 | I15: #N/A | J15: 3096539.5 | K15: 544057.86 | L15: 2208.5055 | M15: 151974 | N15: 1108.564 | O15: 9290.2 | P15: 11930.7 | Q15: 68873 | R15: 103093 | S15: 31890.1 | T15: 50538.6 | U15: 413440 | V15: 36832.4 | W15: 36766.1 | X15: 754375.19 | Y15: #N/A | Z15: #N/A | AA15: #N/A
A16: 962 | B16: 35246 | C16: 847.7 | D16: 60073 | E16: 42570.9 | F16: 249413 | G16: 5533 | H16: 23244 | I16: #N/A | J16: 3085808 | K16: 550195.59 | L16: 2366.5286 | M16: 156181 | N16: 1120.705 | O16: 9104.6 | P16: 12073.6 | Q16: 70491 | R16: 106025 | S16: 31729.9 | T16: 47911.5 | U16: 403282 | V16: 37936.2 | W16: 35886.1 | X16: 792498 | Y16: #N/A | Z16: #N/A | AA16: #N/A | AC16: =B16 -> 35246 | AD16: =IF(AND(ISNUMBER(C15),ISNUMBER(C16)),100*(C16/C15-1),"") -> 2.515419 | AE16: =IF(AND(ISNUMBER(D15),ISNUMBER(D16)),100*(D16/D15-1),"") -> 0.81730608 | AF16: =IF(AND(ISNUMBER(E15),ISNUMBER(E16)),100*(E16/E15-1),"") -> 4.6384556 | AG16: =IF(AND(ISNUMBER(F15),ISNUMBER(F16)),100*(F16/F15-1),"") -> -0.49510481 | AH16: =IF(AND(ISNUMBER(G15),ISNUMBER(G16)),100*(G16/G15-1),"") -> 3.0353818 | AI16: =IF(AND(ISNUMBER(H15),ISNUMBER(H16)),100*(H16/H15-1),"") -> 1.9607843 | AJ16: =IF(AND(ISNUMBER(I15),ISNUMBER(I16)),100*(I16/I15-1),"") | AK16: =IF(AND(ISNUMBER(J15),ISNUMBER(J16)),100*(J16/J15-1),"") -> -0.34656429 | ... BB16: =IF(AND(ISNUMBER(AA15),ISNUMBER(AA16)),100*(AA16/AA15-1),"") | BD16: =AC16 -> 35246 | BE16: =IF(AND(ISNUMBER(C15),ISNUMBER(C16)),INDEX('Country weights'!$B$6:$FB$133,MATCH(Goods!$BD16,'Country weights'!$A$6:$A$133,0),MATCH(Goods!BE$1,'Country weights'!$B$3:$FB$3,0)),"") -> 0.21383864 | BF16: =IF(AND(ISNUMBER(D15),ISNUMBER(D16)),INDEX('Country weights'!$B$6:$FB$133,MATCH(Goods!$BD16,'Country weights'!$A$6:$A$133,0),MATCH(Goods!BF$1,'Country weights'!$B$3:$FB$3,0)),"") -> 0.081584318 | BG16: =IF(AND(ISNUMBER(E15),ISNUMBER(E16)),INDEX('Country weights'!$B$6:$FB$133,MATCH(Goods!$BD16,'Country weights'!$A$6:$A$133,0),MATCH(Goods!BG$1,'Country weights'!$B$3:$FB$3,0)),"") -> 0.098077266 | BH16: =IF(AND(ISNUMBER(F15),ISNUMBER(F16)),INDEX('Country weights'!$B$6:$FB$133,MATCH(Goods!$BD16,'Country weights'!$A$6:$A$133,0),MATCH(Goods!BH$1,'Country weights'!$B$3:$FB$3,0)),"") -> 0.046388023 | BI16: =IF(AND(ISNUMBER(G15),ISNUMBER(G16)),INDEX('Country weights'!$B$6:$FB$133,MATCH(Goods!$BD16,'Country weights'!$A$6:$A$133,0),MATCH(Goods!BI$1,'Country weights'!$B$3:$FB$3,0)),"") -> 0.0041524675 | BJ16: =IF(AND(ISNUMBER(H15),ISNUMBER(H16)),INDEX('Country weights'!$B$6:$FB$133,MATCH(Goods!$BD16,'Country weights'!$A$6:$A$133,0),MATCH(Goods!BJ$1,'Country weights'!$B$3:$FB$3,0)),"") -> 0.017794779 | BK16: =IF(AND(ISNUMBER(I15),ISNUMBER(I16)),INDEX('Country weights'!$B$6:$FB$133,MATCH(Goods!$BD16,'Country weights'!$A$6:$A$133,0),MATCH(Goods!BK$1,'Country weights'!$B$3:$FB$3,0)),"") | BL16: =IF(AND(ISNUMBER(J15),ISNUMBER(J16)),INDEX('Country weights'!$B$6:$FB$133,MATCH(Goods!$BD16,'Country weights'!$A$6:$A$133,0),MATCH(Goods!BL$1,'Country weights'!$B$3:$FB$3,0)),"") -> 0.0047225617 | ... CC16: =IF(AND(ISNUMBER(AA15),ISNUMBER(AA16)),INDEX('Country weights'!$B$6:$FB$133,MATCH(Goods!$BD16,'Country weights'!$A$6:$A$133,0),MATCH(Goods!CC$1,'Country weights'!$B$3:$FB$3,0)),"") | CD16: =SUM(BE16:CC16) -> 0.7198459 | CF16: =BD16 -> 35246 | CG16: =IF(AND(ISNUMBER(C15),ISNUMBER(C16)),BE16/$CD16,"") -> 0.29706169 | CH16: =IF(AND(ISNUMBER(D15),ISNUMBER(D16)),BF16/$CD16,"") -> 0.11333581 | CI16: =IF(AND(ISNUMBER(E15),ISNUMBER(E16)),BG16/$CD16,"") -> 0.13624759 | CJ16: =IF(AND(ISNUMBER(F15),ISNUMBER(F16)),BH16/$CD16,"") -> 0.064441601 | CK16: =IF(AND(ISNUMBER(G15),ISNUMBER(G16)),BI16/$CD16,"") -> 0.0057685505 | CL16: =IF(AND(ISNUMBER(H15),ISNUMBER(H16)),BJ16/$CD16,"") -> 0.024720262 | CM16: =IF(AND(ISNUMBER(I15),ISNUMBER(I16)),BK16/$CD16,"") | CN16: =IF(AND(ISNUMBER(J15),ISNUMBER(J16)),BL16/$CD16,"") -> 0.0065605176 | ... DE16: =IF(AND(ISNUMBER(AA15),ISNUMBER(AA16)),CC16/$CD16,"") | DF16: =SUM(CG16:DE16) -> 1 | DG16: =SUMPRODUCT(AD16:BB16,CG16:DE16,'Sector weights'!B3:Z3) -> 1.2761664 | DI16: =IF(AND(ISNUMBER(C15),ISNUMBER(C16)),CG16*'Sector weights'!B3,"") -> 0.23434489 | DJ16: =IF(AND(ISNUMBER(D15),ISNUMBER(D16)),CH16*'Sector weights'!C3,"") -> 0.083394801 | DK16: =IF(AND(ISNUMBER(E15),ISNUMBER(E16)),CI16*'Sector weights'!D3,"") -> 0.097441032 | DL16: =IF(AND(ISNUMBER(F15),ISNUMBER(F16)),CJ16*'Sector weights'!E3,"") -> 0.051476965 | DM16: =IF(AND(ISNUMBER(G15),ISNUMBER(G16)),CK16*'Sector weights'!F3,"") -> 0.0041154665 | DN16: =IF(AND(ISNUMBER(H15),ISNUMBER(H16)),CL16*'Sector weights'!G3,"") -> 0.016454431 | DO16: =IF(AND(ISNUMBER(I15),ISNUMBER(I16)),CM16*'Sector weights'!H3,"") | DP16: =IF(AND(ISNUMBER(J15),ISNUMBER(J16)),CN16*'Sector weights'!I3,"") -> 0.005607347 | ... EG16: =IF(AND(ISNUMBER(AA15),ISNUMBER(AA16)),DE16*'Sector weights'!Z3,"") | EH16: =SUM(DI16:EG16) -> 0.77142502 | EI16: =SUMPRODUCT(AD16:BB16,DI16:EG16) -> 1.2761664 | EK16: =CF16 -> 35246 | EL16: =IF(AND(ISNUMBER(C15),ISNUMBER(C16)),DI16/$EH16,"") -> 0.30378181 | EM16: =IF(AND(ISNUMBER(D15),ISNUMBER(D16)),DJ16/$EH16,"") -> 0.10810487 | EN16: =IF(AND(ISNUMBER(E15),ISNUMBER(E16)),DK16/$EH16,"") -> 0.12631303 | EO16: =IF(AND(ISNUMBER(F15),ISNUMBER(F16)),DL16/$EH16,"") -> 0.066729707 | EP16: =IF(AND(ISNUMBER(G15),ISNUMBER(G16)),DM16/$EH16,"") -> 0.0053348886 | EQ16: =IF(AND(ISNUMBER(H15),ISNUMBER(H16)),DN16/$EH16,"") -> 0.021329916 | ER16: =IF(AND(ISNUMBER(I15),ISNUMBER(I16)),DO16/$EH16,"") | ES16: =IF(AND(ISNUMBER(J15),ISNUMBER(J16)),DP16/$EH16,"") -> 0.0072688167 | ... FJ16: =IF(AND(ISNUMBER(AA15),ISNUMBER(AA16)),EG16/$EH16,"") | FK16: =SUM(EL16:FJ16) -> 1 | FL16: =SUMPRODUCT(AD16:BB16,EL16:FJ16) -> 1.6542974
A17: 963 | B17: 35338 | C17: 876.4 | D17: 61441 | E17: 42280.1 | F17: 259937 | G17: 5792 | H17: 23348 | I17: #N/A | J17: 3120462.1 | K17: 582148.99 | L17: 2146.9921 | M17: 160353 | N17: 1196.346 | O17: 9374.2 | P17: 12221 | Q17: 70798 | R17: 110283 | S17: 31280.1 | T17: 59169.8 | U17: 412807 | V17: 39118 | W17: 35110.8 | X17: 779677.04 | Y17: #N/A | Z17: #N/A | AA17: #N/A | AC17: =B17 -> 35338 | AD17: =IF(AND(ISNUMBER(C16),ISNUMBER(C17)),100*(C17/C16-1),"") -> 3.3856317 | AE17: =IF(AND(ISNUMBER(D16),ISNUMBER(D17)),100*(D17/D16-1),"") -> 2.2772294 | AF17: =IF(AND(ISNUMBER(E16),ISNUMBER(E17)),100*(E17/E16-1),"") -> -0.68309573 | AG17: =IF(AND(ISNUMBER(F16),ISNUMBER(F17)),100*(F17/F16-1),"") -> 4.2195074 | AH17: =IF(AND(ISNUMBER(G16),ISNUMBER(G17)),100*(G17/G16-1),"") -> 4.6810049 | AI17: =IF(AND(ISNUMBER(H16),ISNUMBER(H17)),100*(H17/H16-1),"") -> 0.44742729 | AJ17: =IF(AND(ISNUMBER(I16),ISNUMBER(I17)),100*(I17/I16-1),"") | AK17: =IF(AND(ISNUMBER(J16),ISNUMBER(J17)),100*(J17/J16-1),"") -> 1.1230154 | ... BB17: =IF(AND(ISNUMBER(AA16),ISNUMBER(AA17)),100*(AA17/AA16-1),"") | BD17: =AC17 -> 35338 | BE17: =IF(AND(ISNUMBER(C16),ISNUMBER(C17)),INDEX('Country weights'!$B$6:$FB$133,MATCH(Goods!$BD17,'Country weights'!$A$6:$A$133,0),MATCH(Goods!BE$1,'Country weights'!$B$3:$FB$3,0)),"") -> 0.21383864 | BF17: =IF(AND(ISNUMBER(D16),ISNUMBER(D17)),INDEX('Country weights'!$B$6:$FB$133,MATCH(Goods!$BD17,'Country weights'!$A$6:$A$133,0),MATCH(Goods!BF$1,'Country weights'!$B$3:$FB$3,0)),"") -> 0.081584318 | BG17: =IF(AND(ISNUMBER(E16),ISNUMBER(E17)),INDEX('Country weights'!$B$6:$FB$133,MATCH(Goods!$BD17,'Country weights'!$A$6:$A$133,0),MATCH(Goods!BG$1,'Country weights'!$B$3:$FB$3,0)),"") -> 0.098077266 | BH17: =IF(AND(ISNUMBER(F16),ISNUMBER(F17)),INDEX('Country weights'!$B$6:$FB$133,MATCH(Goods!$BD17,'Country weights'!$A$6:$A$133,0),MATCH(Goods!BH$1,'Country weights'!$B$3:$FB$3,0)),"") -> 0.046388023 | BI17: =IF(AND(ISNUMBER(G16),ISNUMBER(G17)),INDEX('Country weights'!$B$6:$FB$133,MATCH(Goods!$BD17,'Country weights'!$A$6:$A$133,0),MATCH(Goods!BI$1,'Country weights'!$B$3:$FB$3,0)),"") -> 0.0041524675 | BJ17: =IF(AND(ISNUMBER(H16),ISNUMBER(H17)),INDEX('Country weights'!$B$6:$FB$133,MATCH(Goods!$BD17,'Country weights'!$A$6:$A$133,0),MATCH(Goods!BJ$1,'Country weights'!$B$3:$FB$3,0)),"") -> 0.017794779 | BK17: =IF(AND(ISNUMBER(I16),ISNUMBER(I17)),INDEX('Country weights'!$B$6:$FB$133,MATCH(Goods!$BD17,'Country weights'!$A$6:$A$133,0),MATCH(Goods!BK$1,'Country weights'!$B$3:$FB$3,0)),"") | BL17: =IF(AND(ISNUMBER(J16),ISNUMBER(J17)),INDEX('Country weights'!$B$6:$FB$133,MATCH(Goods!$BD17,'Country weights'!$A$6:$A$133,0),MATCH(Goods!BL$1,'Country weights'!$B$3:$FB$3,0)),"") -> 0.0047225617 | ... CC17: =IF(AND(ISNUMBER(AA16),ISNUMBER(AA17)),INDEX('Country weights'!$B$6:$FB$133,MATCH(Goods!$BD17,'Country weights'!$A$6:$A$133,0),MATCH(Goods!CC$1,'Country weights'!$B$3:$FB$3,0)),"") | CD17: =SUM(BE17:CC17) -> 0.7198459 | CF17: =BD17 -> 35338 | CG17: =IF(AND(ISNUMBER(C16),ISNUMBER(C17)),BE17/$CD17,"") -> 0.29706169 | CH17: =IF(AND(ISNUMBER(D16),ISNUMBER(D17)),BF17/$CD17,"") -> 0.11333581 | CI17: =IF(AND(ISNUMBER(E16),ISNUMBER(E17)),BG17/$CD17,"") -> 0.13624759 | CJ17: =IF(AND(ISNUMBER(F16),ISNUMBER(F17)),BH17/$CD17,"") -> 0.064441601 | CK17: =IF(AND(ISNUMBER(G16),ISNUMBER(G17)),BI17/$CD17,"") -> 0.0057685505 | CL17: =IF(AND(ISNUMBER(H16),ISNUMBER(H17)),BJ17/$CD17,"") -> 0.024720262 | CM17: =IF(AND(ISNUMBER(I16),ISNUMBER(I17)),BK17/$CD17,"") | CN17: =IF(AND(ISNUMBER(J16),ISNUMBER(J17)),BL17/$CD17,"") -> 0.0065605176 | ... DE17: =IF(AND(ISNUMBER(AA16),ISNUMBER(AA17)),CC17/$CD17,"") | DF17: =SUM(CG17:DE17) -> 1 | DG17: =SUMPRODUCT(AD17:BB17,CG17:DE17,'Sector weights'!B4:Z4) -> 1.8039551 | DI17: =IF(AND(ISNUMBER(C16),ISNUMBER(C17)),CG17*'Sector weights'!B4,"") -> 0.23516921 | DJ17: =IF(AND(ISNUMBER(D16),ISNUMBER(D17)),CH17*'Sector weights'!C4,"") -> 0.083009292 | DK17: =IF(AND(ISNUMBER(E16),ISNUMBER(E17)),CI17*'Sector weights'!D4,"") -> 0.098898381 | DL17: =IF(AND(ISNUMBER(F16),ISNUMBER(F17)),CJ17*'Sector weights'!E4,"") -> 0.051262453 | DM17: =IF(AND(ISNUMBER(G16),ISNUMBER(G17)),CK17*'Sector weights'!F4,"") -> 0.0041429634 | DN17: =IF(AND(ISNUMBER(H16),ISNUMBER(H17)),CL17*'Sector weights'!G4,"") -> 0.01645469 | DO17: =IF(AND(ISNUMBER(I16),ISNUMBER(I17)),CM17*'Sector weights'!H4,"") | DP17: =IF(AND(ISNUMBER(J16),ISNUMBER(J17)),CN17*'Sector weights'!I4,"") -> 0.0055546112 | ... EG17: =IF(AND(ISNUMBER(AA16),ISNUMBER(AA17)),DE17*'Sector weights'!Z4,"") | EH17: =SUM(DI17:EG17) -> 0.77252123 | EI17: =SUMPRODUCT(AD17:BB17,DI17:EG17) -> 1.8039551 | EK17: =CF17 -> 35338 | EL17: =IF(AND(ISNUMBER(C16),ISNUMBER(C17)),DI17/$EH17,"") -> 0.3044178 | EM17: =IF(AND(ISNUMBER(D16),ISNUMBER(D17)),DJ17/$EH17,"") -> 0.10745244 | EN17: =IF(AND(ISNUMBER(E16),ISNUMBER(E17)),DK17/$EH17,"") -> 0.12802028 | EO17: =IF(AND(ISNUMBER(F16),ISNUMBER(F17)),DL17/$EH17,"") -> 0.066357339 | EP17: =IF(AND(ISNUMBER(G16),ISNUMBER(G17)),DM17/$EH17,"") -> 0.0053629121 | EQ17: =IF(AND(ISNUMBER(H16),ISNUMBER(H17)),DN17/$EH17,"") -> 0.021299984 | ER17: =IF(AND(ISNUMBER(I16),ISNUMBER(I17)),DO17/$EH17,"") | ES17: =IF(AND(ISNUMBER(J16),ISNUMBER(J17)),DP17/$EH17,"") -> 0.0071902377 | ... FJ17: =IF(AND(ISNUMBER(AA16),ISNUMBER(AA17)),EG17/$EH17,"") | FK17: =SUM(EL17:FJ17) -> 1 | FL17: =SUMPRODUCT(AD17:BB17,EL17:FJ17) -> 2.3351528
A18: 964 | B18: 35430 | C18: 897.7 | D18: 62011 | E18: 42647.9 | F18: 265252 | G18: 5562 | H18: 24477 | I18: #N/A | J18: 3403040.9 | K18: 620228.49 | L18: 2859.2585 | M18: 159657 | N18: 1233.796 | O18: 9810.2 | P18: 12739.7 | Q18: 71105 | R18: 116728 | S18: 32815 | T18: 46744.8 | U18: 427643 | V18: 40496 | W18: 37797 | X18: 838608.86 | Y18: #N/A | Z18: #N/A | AA18: #N/A | AC18: =B18 -> 35430 | AD18: =IF(AND(ISNUMBER(C17),ISNUMBER(C18)),100*(C18/C17-1),"") -> 2.4303971 | AE18: =IF(AND(ISNUMBER(D17),ISNUMBER(D18)),100*(D18/D17-1),"") -> 0.92771928 | AF18: =IF(AND(ISNUMBER(E17),ISNUMBER(E18)),100*(E18/E17-1),"") -> 0.8699128 | AG18: =IF(AND(ISNUMBER(F17),ISNUMBER(F18)),100*(F18/F17-1),"") -> 2.0447262 | AH18: =IF(AND(ISNUMBER(G17),ISNUMBER(G18)),100*(G18/G17-1),"") -> -3.9709945 | AI18: =IF(AND(ISNUMBER(H17),ISNUMBER(H18)),100*(H18/H17-1),"") -> 4.835532 | AJ18: =IF(AND(ISNUMBER(I17),ISNUMBER(I18)),100*(I18/I17-1),"") | AK18: =IF(AND(ISNUMBER(J17),ISNUMBER(J18)),100*(J18/J17-1),"") -> 9.0556716 | ... BB18: =IF(AND(ISNUMBER(AA17),ISNUMBER(AA18)),100*(AA18/AA17-1),"") | BD18: =AC18 -> 35430 | BE18: =IF(AND(ISNUMBER(C17),ISNUMBER(C18)),INDEX('Country weights'!$B$6:$FB$133,MATCH(Goods!$BD18,'Country weights'!$A$6:$A$133,0),MATCH(Goods!BE$1,'Country weights'!$B$3:$FB$3,0)),"") -> 0.21383864 | BF18: =IF(AND(ISNUMBER(D17),ISNUMBER(D18)),INDEX('Country weights'!$B$6:$FB$133,MATCH(Goods!$BD18,'Country weights'!$A$6:$A$133,0),MATCH(Goods!BF$1,'Country weights'!$B$3:$FB$3,0)),"") -> 0.081584318 | BG18: =IF(AND(ISNUMBER(E17),ISNUMBER(E18)),INDEX('Country weights'!$B$6:$FB$133,MATCH(Goods!$BD18,'Country weights'!$A$6:$A$133,0),MATCH(Goods!BG$1,'Country weights'!$B$3:$FB$3,0)),"") -> 0.098077266 | BH18: =IF(AND(ISNUMBER(F17),ISNUMBER(F18)),INDEX('Country weights'!$B$6:$FB$133,MATCH(Goods!$BD18,'Country weights'!$A$6:$A$133,0),MATCH(Goods!BH$1,'Country weights'!$B$3:$FB$3,0)),"") -> 0.046388023 | BI18: =IF(AND(ISNUMBER(G17),ISNUMBER(G18)),INDEX('Country weights'!$B$6:$FB$133,MATCH(Goods!$BD18,'Country weights'!$A$6:$A$133,0),MATCH(Goods!BI$1,'Country weights'!$B$3:$FB$3,0)),"") -> 0.0041524675 | BJ18: =IF(AND(ISNUMBER(H17),ISNUMBER(H18)),INDEX('Country weights'!$B$6:$FB$133,MATCH(Goods!$BD18,'Country weights'!$A$6:$A$133,0),MATCH(Goods!BJ$1,'Country weights'!$B$3:$FB$3,0)),"") -> 0.017794779 | BK18: =IF(AND(ISNUMBER(I17),ISNUMBER(I18)),INDEX('Country weights'!$B$6:$FB$133,MATCH(Goods!$BD18,'Country weights'!$A$6:$A$133,0),MATCH(Goods!BK$1,'Country weights'!$B$3:$FB$3,0)),"") | BL18: =IF(AND(ISNUMBER(J17),ISNUMBER(J18)),INDEX('Country weights'!$B$6:$FB$133,MATCH(Goods!$BD18,'Country weights'!$A$6:$A$133,0),MATCH(Goods!BL$1,'Country weights'!$B$3:$FB$3,0)),"") -> 0.0047225617 | ... CC18: =IF(AND(ISNUMBER(AA17),ISNUMBER(AA18)),INDEX('Country weights'!$B$6:$FB$133,MATCH(Goods!$BD18,'Country weights'!$A$6:$A$133,0),MATCH(Goods!CC$1,'Country weights'!$B$3:$FB$3,0)),"") | CD18: =SUM(BE18:CC18) -> 0.7198459 | CF18: =BD18 -> 35430 | CG18: =IF(AND(ISNUMBER(C17),ISNUMBER(C18)),BE18/$CD18,"") -> 0.29706169 | CH18: =IF(AND(ISNUMBER(D17),ISNUMBER(D18)),BF18/$CD18,"") -> 0.11333581 | CI18: =IF(AND(ISNUMBER(E17),ISNUMBER(E18)),BG18/$CD18,"") -> 0.13624759 | CJ18: =IF(AND(ISNUMBER(F17),ISNUMBER(F18)),BH18/$CD18,"") -> 0.064441601 | CK18: =IF(AND(ISNUMBER(G17),ISNUMBER(G18)),BI18/$CD18,"") -> 0.0057685505 | CL18: =IF(AND(ISNUMBER(H17),ISNUMBER(H18)),BJ18/$CD18,"") -> 0.024720262 | CM18: =IF(AND(ISNUMBER(I17),ISNUMBER(I18)),BK18/$CD18,"") | CN18: =IF(AND(ISNUMBER(J17),ISNUMBER(J18)),BL18/$CD18,"") -> 0.0065605176 | ... DE18: =IF(AND(ISNUMBER(AA17),ISNUMBER(AA18)),CC18/$CD18,"") | DF18: =SUM(CG18:DE18) -> 1 | DG18: =SUMPRODUCT(AD18:BB18,CG18:DE18,'Sector weights'!B5:Z5) -> 2.0719505 | DI18: =IF(AND(ISNUMBER(C17),ISNUMBER(C18)),CG18*'Sector weights'!B5,"") -> 0.23560621 | DJ18: =IF(AND(ISNUMBER(D17),ISNUMBER(D18)),CH18*'Sector weights'!C5,"") -> 0.083277111 | DK18: =IF(AND(ISNUMBER(E17),ISNUMBER(E18)),CI18*'Sector weights'!D5,"") -> 0.098350091 | DL18: =IF(AND(ISNUMBER(F17),ISNUMBER(F18)),CJ18*'Sector weights'!E5,"") -> 0.051477591 | DM18: =IF(AND(ISNUMBER(G17),ISNUMBER(G18)),CK18*'Sector weights'!F5,"") -> 0.0042005839 | DN18: =IF(AND(ISNUMBER(H17),ISNUMBER(H18)),CL18*'Sector weights'!G5,"") -> 0.0164473 | DO18: =IF(AND(ISNUMBER(I17),ISNUMBER(I18)),CM18*'Sector weights'!H5,"") | DP18: =IF(AND(ISNUMBER(J17),ISNUMBER(J18)),CN18*'Sector weights'!I5,"") -> 0.0055625086 | ... EG18: =IF(AND(ISNUMBER(AA17),ISNUMBER(AA18)),DE18*'Sector weights'!Z5,"") | EH18: =SUM(DI18:EG18) -> 0.7740904 | EI18: =SUMPRODUCT(AD18:BB18,DI18:EG18) -> 2.0719505 | EK18: =CF18 -> 35430 | EL18: =IF(AND(ISNUMBER(C17),ISNUMBER(C18)),DI18/$EH18,"") -> 0.30436524 | EM18: =IF(AND(ISNUMBER(D17),ISNUMBER(D18)),DJ18/$EH18,"") -> 0.1075806 | EN18: =IF(AND(ISNUMBER(E17),ISNUMBER(E18)),DK18/$EH18,"") -> 0.12705246 | EO18: =IF(AND(ISNUMBER(F17),ISNUMBER(F18)),DL18/$EH18,"") -> 0.066500748 | EP18: =IF(AND(ISNUMBER(G17),ISNUMBER(G18)),DM18/$EH18,"") -> 0.0054264773 | EQ18: =IF(AND(ISNUMBER(H17),ISNUMBER(H18)),DN18/$EH18,"") -> 0.021247261 | ER18: =IF(AND(ISNUMBER(I17),ISNUMBER(I18)),DO18/$EH18,"") | ES18: =IF(AND(ISNUMBER(J17),ISNUMBER(J18)),DP18/$EH18,"") -> 0.0071858643 | ... FJ18: =IF(AND(ISNUMBER(AA17),ISNUMBER(AA18)),EG18/$EH18,"") | FK18: =SUM(EL18:FJ18) -> 1 | FL18: =SUMPRODUCT(AD18:BB18,EL18:FJ18) -> 2.676626
